*** Starting uWSGI 2.0.19.1 (64bit) on [Mon Nov  2 09:47:43 2020] ***
compiled with version: 7.5.0 on 02 November 2020 08:13:32
os: Linux-5.4.0-1031-azure #32~18.04.1-Ubuntu SMP Tue Oct 6 10:03:22 UTC 2020
nodename: focus-dict
machine: x86_64
clock source: unix
detected number of CPU cores: 2
current working directory: /home/azureuser/focus_dict
detected binary path: /home/azureuser/focus_dict/env/bin/uwsgi
!!! no internal routing support, rebuild with pcre support !!!
your processes number limit is 31597
your memory page size is 4096 bytes
detected max file descriptor number: 1024
lock engine: pthread robust mutexes
thunder lock: disabled (you can enable it with --thunder-lock)
uwsgi socket 0 bound to UNIX address focus_dict.sock fd 3
Python version: 3.6.9 (default, Oct  8 2020, 12:12:24)  [GCC 8.4.0]
*** Python threads support is disabled. You can enable it with --enable-threads ***
Python main interpreter initialized at 0x5633321894d0
your server socket listen backlog is limited to 100 connections
your mercy for graceful operations on workers is 60 seconds
mapped 437520 bytes (427 KB) for 5 cores
*** Operational MODE: preforking ***
Traceback (most recent call last):
  File "./wsgi.py", line 1, in <module>
    from focus_dict import app
  File "./focus_dict/__init__.py", line 11, in <module>
    from focus_dict import routes
  File "./focus_dict/routes.py", line 86
    global conn
              ^
TabError: inconsistent use of tabs and spaces in indentation
unable to load app 0 (mountpoint='') (callable not found or import error)
*** no app loaded. going in full dynamic mode ***
*** uWSGI is running in multiple interpreter mode ***
spawned uWSGI master process (pid: 5584)
spawned uWSGI worker 1 (pid: 5621, cores: 1)
spawned uWSGI worker 2 (pid: 5622, cores: 1)
spawned uWSGI worker 3 (pid: 5623, cores: 1)
spawned uWSGI worker 4 (pid: 5624, cores: 1)
spawned uWSGI worker 5 (pid: 5625, cores: 1)
--- no python application found, check your startup logs for errors ---
[pid: 5624|app: -1|req: -1/1] 196.53.10.120 () {42 vars in 788 bytes} [Mon Nov  2 09:47:49 2020] GET / => generated 21 bytes in 0 msecs (HTTP/1.1 500) 2 headers in 83 bytes (0 switches on core 0)
SIGINT/SIGQUIT received...killing workers...
worker 1 buried after 1 seconds
worker 2 buried after 3 seconds
worker 3 buried after 3 seconds
worker 4 buried after 3 seconds
worker 5 buried after 3 seconds
goodbye to uWSGI.
VACUUM: unix socket focus_dict.sock removed.
*** Starting uWSGI 2.0.19.1 (64bit) on [Mon Nov  2 09:49:52 2020] ***
compiled with version: 7.5.0 on 02 November 2020 08:13:32
os: Linux-5.4.0-1031-azure #32~18.04.1-Ubuntu SMP Tue Oct 6 10:03:22 UTC 2020
nodename: focus-dict
machine: x86_64
clock source: unix
detected number of CPU cores: 2
current working directory: /home/azureuser/focus_dict
detected binary path: /home/azureuser/focus_dict/env/bin/uwsgi
!!! no internal routing support, rebuild with pcre support !!!
your processes number limit is 31597
your memory page size is 4096 bytes
detected max file descriptor number: 1024
lock engine: pthread robust mutexes
thunder lock: disabled (you can enable it with --thunder-lock)
uwsgi socket 0 bound to UNIX address focus_dict.sock fd 3
Python version: 3.6.9 (default, Oct  8 2020, 12:12:24)  [GCC 8.4.0]
*** Python threads support is disabled. You can enable it with --enable-threads ***
Python main interpreter initialized at 0x55d34be7a4d0
your server socket listen backlog is limited to 100 connections
your mercy for graceful operations on workers is 60 seconds
mapped 437520 bytes (427 KB) for 5 cores
*** Operational MODE: preforking ***
WSGI app 0 (mountpoint='') ready in 0 seconds on interpreter 0x55d34be7a4d0 pid: 5698 (default app)
*** uWSGI is running in multiple interpreter mode ***
spawned uWSGI master process (pid: 5698)
spawned uWSGI worker 1 (pid: 5742, cores: 1)
spawned uWSGI worker 2 (pid: 5743, cores: 1)
spawned uWSGI worker 3 (pid: 5744, cores: 1)
spawned uWSGI worker 4 (pid: 5745, cores: 1)
spawned uWSGI worker 5 (pid: 5746, cores: 1)
[pid: 5746|app: 0|req: 1/1] 196.53.10.120 () {42 vars in 788 bytes} [Mon Nov  2 09:50:00 2020] GET / => generated 19362 bytes in 13 msecs (HTTP/1.1 200) 2 headers in 82 bytes (1 switches on core 0)
[pid: 5745|app: 0|req: 1/2] 196.53.10.120 () {50 vars in 1045 bytes} [Mon Nov  2 09:50:01 2020] POST /index => generated 43867 bytes in 200 msecs (HTTP/1.1 200) 2 headers in 82 bytes (1 switches on core 0)
[pid: 5746|app: 0|req: 2/3] 196.53.10.120 () {42 vars in 822 bytes} [Mon Nov  2 09:50:02 2020] GET /fonts/glyphicons-halflings-regular.woff2 => generated 232 bytes in 0 msecs (HTTP/1.1 404) 2 headers in 87 bytes (1 switches on core 0)
[pid: 5744|app: 0|req: 1/4] 196.53.10.120 () {42 vars in 820 bytes} [Mon Nov  2 09:50:02 2020] GET /fonts/glyphicons-halflings-regular.woff => generated 232 bytes in 2 msecs (HTTP/1.1 404) 2 headers in 87 bytes (1 switches on core 0)
[pid: 5743|app: 0|req: 1/5] 196.53.10.120 () {42 vars in 818 bytes} [Mon Nov  2 09:50:02 2020] GET /fonts/glyphicons-halflings-regular.ttf => generated 232 bytes in 2 msecs (HTTP/1.1 404) 2 headers in 87 bytes (1 switches on core 0)
Traceback (most recent call last):
  File "/home/azureuser/focus_dict/env/lib/python3.6/site-packages/flask/app.py", line 2464, in __call__
    return self.wsgi_app(environ, start_response)
  File "/home/azureuser/focus_dict/env/lib/python3.6/site-packages/flask/app.py", line 2450, in wsgi_app
    response = self.handle_exception(e)
  File "/home/azureuser/focus_dict/env/lib/python3.6/site-packages/flask/app.py", line 1867, in handle_exception
    reraise(exc_type, exc_value, tb)
  File "/home/azureuser/focus_dict/env/lib/python3.6/site-packages/flask/_compat.py", line 39, in reraise
    raise value
  File "/home/azureuser/focus_dict/env/lib/python3.6/site-packages/flask/app.py", line 2447, in wsgi_app
    response = self.full_dispatch_request()
  File "/home/azureuser/focus_dict/env/lib/python3.6/site-packages/flask/app.py", line 1952, in full_dispatch_request
    rv = self.handle_user_exception(e)
  File "/home/azureuser/focus_dict/env/lib/python3.6/site-packages/flask/app.py", line 1821, in handle_user_exception
    reraise(exc_type, exc_value, tb)
  File "/home/azureuser/focus_dict/env/lib/python3.6/site-packages/flask/_compat.py", line 39, in reraise
    raise value
  File "/home/azureuser/focus_dict/env/lib/python3.6/site-packages/flask/app.py", line 1950, in full_dispatch_request
    rv = self.dispatch_request()
  File "/home/azureuser/focus_dict/env/lib/python3.6/site-packages/flask/app.py", line 1936, in dispatch_request
    return self.view_functions[rule.endpoint](**req.view_args)
  File "./focus_dict/routes.py", line 127, in batch
    ind = pair['index']
TypeError: 'NoneType' object is not subscriptable
[pid: 5744|app: 0|req: 2/6] 196.53.10.120 () {50 vars in 1050 bytes} [Mon Nov  2 09:50:04 2020] POST /batch => generated 0 bytes in 16 msecs (HTTP/1.1 500) 0 headers in 0 bytes (0 switches on core 0)
